Workbook

Sheet A_N_B_vol_plein
A1: Geldig/valable | C1: Volledige werkloosheidsuitkeringen - dagbedrag van de volle uitkering | U1: Multiplicat(o)(eu)r | W1: =Basisbedragen!$I$2 -> 1.8114
A2: 46266 | C2: Allocations de chômage complet - montant journalier de l'allocation entière
C4: Werknemers met gezinslast Travailleurs ayant charge de famille | I4: Alleenwonenden Isolés | O4: Samenwonenden Cohabitants
C6: 1e periode | G6: 2e per | I6: 1e periode | M6: 2e per | O6: 1e periode | S6: 2e per | T6: 2ème pér
D7: 1ère période | G7: 2ème pér | J7: 1ère période | M7: 2ème pér | P7: 1ère période | S7: BV+ / PP+ | T7: BV- / PP-
A9: Code | C9: AA1 | D9: AA2 | E9: AA3 | G9: AB AX | I9: NA1 | J9: NA2 | K9: NA3 | M9: NB NX | O9: BA1 | P9: BA2 | Q9: BA3 | S9: BX | T9: BB
O10: 0.65 | P10: 0.6 | Q10: 0.6
C11: 0.65 | D11: 0.6 | E11: 0.6 | I11: 0.65 | J11: 0.6 | K11: 0.6 | O11: 0.65 | P11: 0.6 | Q11: 0.6
A12: MIN | C12: =ROUND(Basisbedragen!$D$34*$W$1,2) -> 78.09 | D12: =$C$12 -> 78.09 | E12: =ROUND(Basisbedragen!$D$35*$W$1,2) -> 70.99 | G12: =$E$12 -> 70.99 | I12: =ROUND(Basisbedragen!$D$36*$W$1,2) -> 63.29 | J12: =$I$12 -> 63.29 | K12: =ROUND(Basisbedragen!$D$37*$W$1,2) -> 57.53 | M12: =$K$12 -> 57.53 | O12: =ROUND(Basisbedragen!$D$38*$W$1,2) -> 60.92 | P12: =ROUND(Basisbedragen!$D$39*$W$1,2) -> 56.23 | Q12: =ROUND(Basisbedragen!$D$40*$W$1,2) -> 51.12 | S12: =ROUND(Basisbedragen!D41*$W$1,2) -> 42.37 | T12: =ROUND(Basisbedragen!D42*$W$1,2) -> 29.85
A13: 1 | C13: =IF(MIN(MAX(ROUND(ROUND('Loonschijven_Tranches salariale'!$Q8*0.65,4)*Basisbedragen!$I$7,2),ROUND(Basisbedragen!$D$34*Basisbedragen!$I$7,2)),ROUND(ROUND(Basisbedragen!$D$27*0.65,4)*Basisbedragen!$I$7,2))<= Basisbedragen!$I$8,MIN(MAX(ROUND(ROUND('Loonschijven_Tranches salariale'!$Q8*0.65,4)*Basisbedragen!$I$2,2),ROUND(Basisbedragen!$D$34*Basisbedragen!$I$2,2)),ROUND(ROUND(Basisbedragen!$D$27*0.65,4)*Basisbedragen!$I$2,2)),MIN(MAX(ROUND(ROUND('Loonschijven_Tranches salariale'!$Q8*0.65,4)*Basisbedragen!$I$7,2),ROUND(Basisbedragen!$D$34*Basisbedragen!$I$7,2)),ROUND(ROUND(Basisbedragen!$D$27*0.65,4)*Basisbedragen!$I$7,2))+Basisbedragen!$I$10) -> 78.09 | D13: =IF(MIN(MAX(ROUND(ROUND('Loonschijven_Tranches salariale'!$Q8*0.6,4)*Basisbedragen!$I$7,2),ROUND(Basisbedragen!$D$34*Basisbedragen!$I$7,2)),ROUND(ROUND(Basisbedragen!$D$28*0.6,4)*Basisbedragen!$I$7,2))<= Basisbedragen!$I$8,MIN(MAX(ROUND(ROUND('Loonschijven_Tranches salariale'!$Q8*0.6,4)*Basisbedragen!$I$2,2),ROUND(Basisbedragen!$D$34*Basisbedragen!$I$2,2)),ROUND(ROUND(Basisbedragen!$D$28*0.6,4)*Basisbedragen!$I$2,2)),MIN(MAX(ROUND(ROUND('Loonschijven_Tranches salariale'!$Q8*0.6,4)*Basisbedragen!$I$7,2),ROUND(Basisbedragen!$D$34*Basisbedragen!$I$7,2)),ROUND(ROUND(Basisbedragen!$D$28*0.6,4)*Basisbedragen!$I$7,2))+Basisbedragen!$I$10) -> 78.09 | E13: =MIN(MAX(ROUND(ROUND('Loonschijven_Tranches salariale'!$Q8*0.6,4)*Basisbedragen!$I$2,2),ROUND(Basisbedragen!$D$35*Basisbedragen!$I$2,2)),ROUND(ROUND(Basisbedragen!$D$29*0.6,4)*Basisbedragen!$I$2,2)) -> 70.99 | G13: =$E$12 -> 70.99 | I13: =IF(MIN(MAX(ROUND(ROUND('Loonschijven_Tranches salariale'!$Q8*0.65,4)*Basisbedragen!$I$7,2),ROUND(Basisbedragen!$D$36*Basisbedragen!$I$7,2)),ROUND(ROUND(Basisbedragen!$D$27*0.65,4)*Basisbedragen!$I$7,2))<= Basisbedragen!$I$8,MIN(MAX(ROUND(ROUND('Loonschijven_Tranches salariale'!$Q8*0.65,4)*Basisbedragen!$I$2,2),ROUND(Basisbedragen!$D$36*Basisbedragen!$I$2,2)),ROUND(ROUND(Basisbedragen!$D$27*0.65,4)*Basisbedragen!$I$2,2)),MIN(MAX(ROUND(ROUND('Loonschijven_Tranches salariale'!$Q8*0.65,4)*Basisbedragen!$I$7,2),ROUND(Basisbedragen!$D$36*Basisbedragen!$I$7,2)),ROUND(ROUND(Basisbedragen!$D$27*0.65,4)*Basisbedragen!$I$7,2))+Basisbedragen!$I$10) -> 63.29 | J13: =IF(MIN(MAX(ROUND(ROUND('Loonschijven_Tranches salariale'!$Q8*0.6,4)*Basisbedragen!$I$7,2),ROUND(Basisbedragen!$D$36*Basisbedragen!$I$7,2)),ROUND(ROUND(Basisbedragen!$D$28*0.6,4)*Basisbedragen!$I$7,2))<= Basisbedragen!$I$8,MIN(MAX(ROUND(ROUND('Loonschijven_Tranches salariale'!$Q8*0.6,4)*Basisbedragen!$I$2,2),ROUND(Basisbedragen!$D$36*Basisbedragen!$I$2,2)),ROUND(ROUND(Basisbedragen!$D$28*0.6,4)*Basisbedragen!$I$2,2)),MIN(MAX(ROUND(ROUND('Loonschijven_Tranches salariale'!$Q8*0.6,4)*Basisbedragen!$I$7,2),ROUND(Basisbedragen!$D$36*Basisbedragen!$I$7,2)),ROUND(ROUND(Basisbedragen!$D$28*0.6,4)*Basisbedragen!$I$7,2))+Basisbedragen!$I$10) -> 63.29 | K13: =MIN(MAX(ROUND(ROUND('Loonschijven_Tranches salariale'!$Q8*0.6,4)*Basisbedragen!$I$2,2),ROUND(Basisbedragen!$D$37*Basisbedragen!$I$2,2)),ROUND(ROUND(Basisbedragen!$D$29*0.6,4)*Basisbedragen!$I$2,2)) -> 57.53 | M13: =$K$12 -> 57.53 | O13: =IF(MIN(MAX(ROUND(ROUND('Loonschijven_Tranches salariale'!$Q8*0.65,4)*Basisbedragen!$I$7,2),ROUND(Basisbedragen!$D$38*Basisbedragen!$I$7,2)),ROUND(ROUND(Basisbedragen!$D$27*0.65,4)*Basisbedragen!$I$7,2))<= Basisbedragen!$I$8,MIN(MAX(ROUND(ROUND('Loonschijven_Tranches salariale'!$Q8*0.65,4)*Basisbedragen!$I$2,2),ROUND(Basisbedragen!$D$38*Basisbedragen!$I$2,2)),ROUND(ROUND(Basisbedragen!$D$27*0.65,4)*Basisbedragen!$I$2,2)),MIN(MAX(ROUND(ROUND('Loonschijven_Tranches salariale'!$Q8*0.65,4)*Basisbedragen!$I$7,2),ROUND(Basisbedragen!$D$38*Basisbedragen!$I$7,2)),ROUND(ROUND(Basisbedragen!$D$27*0.65,4)*Basisbedragen!$I$7,2))+Basisbedragen!$I$10) -> 60.92 | P13: =IF(MIN(MAX(ROUND(ROUND('Loonschijven_Tranches salariale'!$Q8*0.6,4)*Basisbedragen!$I$7,2),ROUND(Basisbedragen!$D$39*Basisbedragen!$I$7,2)),ROUND(ROUND(Basisbedragen!$D$28*0.6,4)*Basisbedragen!$I$7,2))<= Basisbedragen!$I$8,MIN(MAX(ROUND(ROUND('Loonschijven_Tranches salariale'!$Q8*0.6,4)*Basisbedragen!$I$2,2),ROUND(Basisbedragen!$D$39*Basisbedragen!$I$2,2)),ROUND(ROUND(Basisbedragen!$D$28*0.6,4)*Basisbedragen!$I$2,2)),MIN(MAX(ROUND(ROUND('Loonschijven_Tranches salariale'!$Q8*0.6,4)*Basisbedragen!$I$7,2),ROUND(Basisbedragen!$D$39*Basisbedragen!$I$7,2)),ROUND(ROUND(Basisbedragen!$D$28*0.6,4)*Basisbedragen!$I$7,2))+Basisbedragen!$I$10) -> 56.23 | Q13: =MIN(MAX(ROUND(ROUND('Loonschijven_Tranches salariale'!$Q8*0.6,4)*Basisbedragen!$I$2,2),ROUND(Basisbedragen!$D$40*Basisbedragen!$I$2,2)),ROUND(ROUND(Basisbedragen!$D$29*0.6,4)*Basisbedragen!$I$2,2)) -> 51.12 | S13: =$S$12 -> 42.37 | T13: =$T$12 -> 29.85
A14: =A13+1 -> 2 | C14: =IF(MIN(MAX(ROUND(ROUND('Loonschijven_Tranches salariale'!$Q9*0.65,4)*Basisbedragen!$I$7,2),ROUND(Basisbedragen!$D$34*Basisbedragen!$I$7,2)),ROUND(ROUND(Basisbedragen!$D$27*0.65,4)*Basisbedragen!$I$7,2))<= Basisbedragen!$I$8,MIN(MAX(ROUND(ROUND('Loonschijven_Tranches salariale'!$Q9*0.65,4)*Basisbedragen!$I$2,2),ROUND(Basisbedragen!$D$34*Basisbedragen!$I$2,2)),ROUND(ROUND(Basisbedragen!$D$27*0.65,4)*Basisbedragen!$I$2,2)),MIN(MAX(ROUND(ROUND('Loonschijven_Tranches salariale'!$Q9*0.65,4)*Basisbedragen!$I$7,2),ROUND(Basisbedragen!$D$34*Basisbedragen!$I$7,2)),ROUND(ROUND(Basisbedragen!$D$27*0.65,4)*Basisbedragen!$I$7,2))+Basisbedragen!$I$10) -> 78.09 | D14: =IF(MIN(MAX(ROUND(ROUND('Loonschijven_Tranches salariale'!$Q9*0.6,4)*Basisbedragen!$I$7,2),ROUND(Basisbedragen!$D$34*Basisbedragen!$I$7,2)),ROUND(ROUND(Basisbedragen!$D$28*0.6,4)*Basisbedragen!$I$7,2))<= Basisbedragen!$I$8,MIN(MAX(ROUND(ROUND('Loonschijven_Tranches salariale'!$Q9*0.6,4)*Basisbedragen!$I$2,2),ROUND(Basisbedragen!$D$34*Basisbedragen!$I$2,2)),ROUND(ROUND(Basisbedragen!$D$28*0.6,4)*Basisbedragen!$I$2,2)),MIN(MAX(ROUND(ROUND('Loonschijven_Tranches salariale'!$Q9*0.6,4)*Basisbedragen!$I$7,2),ROUND(Basisbedragen!$D$34*Basisbedragen!$I$7,2)),ROUND(ROUND(Basisbedragen!$D$28*0.6,4)*Basisbedragen!$I$7,2))+Basisbedragen!$I$10) -> 78.09 | E14: =MIN(MAX(ROUND(ROUND('Loonschijven_Tranches salariale'!$Q9*0.6,4)*Basisbedragen!$I$2,2),ROUND(Basisbedragen!$D$35*Basisbedragen!$I$2,2)),ROUND(ROUND(Basisbedragen!$D$29*0.6,4)*Basisbedragen!$I$2,2)) -> 70.99 | G14: =$E$12 -> 70.99 | I14: =IF(MIN(MAX(ROUND(ROUND('Loonschijven_Tranches salariale'!$Q9*0.65,4)*Basisbedragen!$I$7,2),ROUND(Basisbedragen!$D$36*Basisbedragen!$I$7,2)),ROUND(ROUND(Basisbedragen!$D$27*0.65,4)*Basisbedragen!$I$7,2))<= Basisbedragen!$I$8,MIN(MAX(ROUND(ROUND('Loonschijven_Tranches salariale'!$Q9*0.65,4)*Basisbedragen!$I$2,2),ROUND(Basisbedragen!$D$36*Basisbedragen!$I$2,2)),ROUND(ROUND(Basisbedragen!$D$27*0.65,4)*Basisbedragen!$I$2,2)),MIN(MAX(ROUND(ROUND('Loonschijven_Tranches salariale'!$Q9*0.65,4)*Basisbedragen!$I$7,2),ROUND(Basisbedragen!$D$36*Basisbedragen!$I$7,2)),ROUND(ROUND(Basisbedragen!$D$27*0.65,4)*Basisbedragen!$I$7,2))+Basisbedragen!$I$10) -> 63.29 | J14: =IF(MIN(MAX(ROUND(ROUND('Loonschijven_Tranches salariale'!$Q9*0.6,4)*Basisbedragen!$I$7,2),ROUND(Basisbedragen!$D$36*Basisbedragen!$I$7,2)),ROUND(ROUND(Basisbedragen!$D$28*0.6,4)*Basisbedragen!$I$7,2))<= Basisbedragen!$I$8,MIN(MAX(ROUND(ROUND('Loonschijven_Tranches salariale'!$Q9*0.6,4)*Basisbedragen!$I$2,2),ROUND(Basisbedragen!$D$36*Basisbedragen!$I$2,2)),ROUND(ROUND(Basisbedragen!$D$28*0.6,4)*Basisbedragen!$I$2,2)),MIN(MAX(ROUND(ROUND('Loonschijven_Tranches salariale'!$Q9*0.6,4)*Basisbedragen!$I$7,2),ROUND(Basisbedragen!$D$36*Basisbedragen!$I$7,2)),ROUND(ROUND(Basisbedragen!$D$28*0.6,4)*Basisbedragen!$I$7,2))+Basisbedragen!$I$10) -> 63.29 | K14: =MIN(MAX(ROUND(ROUND('Loonschijven_Tranches salariale'!$Q9*0.6,4)*Basisbedragen!$I$2,2),ROUND(Basisbedragen!$D$37*Basisbedragen!$I$2,2)),ROUND(ROUND(Basisbedragen!$D$29*0.6,4)*Basisbedragen!$I$2,2)) -> 57.53 | M14: =$K$12 -> 57.53 | O14: =IF(MIN(MAX(ROUND(ROUND('Loonschijven_Tranches salariale'!$Q9*0.65,4)*Basisbedragen!$I$7,2),ROUND(Basisbedragen!$D$38*Basisbedragen!$I$7,2)),ROUND(ROUND(Basisbedragen!$D$27*0.65,4)*Basisbedragen!$I$7,2))<= Basisbedragen!$I$8,MIN(MAX(ROUND(ROUND('Loonschijven_Tranches salariale'!$Q9*0.65,4)*Basisbedragen!$I$2,2),ROUND(Basisbedragen!$D$38*Basisbedragen!$I$2,2)),ROUND(ROUND(Basisbedragen!$D$27*0.65,4)*Basisbedragen!$I$2,2)),MIN(MAX(ROUND(ROUND('Loonschijven_Tranches salariale'!$Q9*0.65,4)*Basisbedragen!$I$7,2),ROUND(Basisbedragen!$D$38*Basisbedragen!$I$7,2)),ROUND(ROUND(Basisbedragen!$D$27*0.65,4)*Basisbedragen!$I$7,2))+Basisbedragen!$I$10) -> 60.92 | P14: =IF(MIN(MAX(ROUND(ROUND('Loonschijven_Tranches salariale'!$Q9*0.6,4)*Basisbedragen!$I$7,2),ROUND(Basisbedragen!$D$39*Basisbedragen!$I$7,2)),ROUND(ROUND(Basisbedragen!$D$28*0.6,4)*Basisbedragen!$I$7,2))<= Basisbedragen!$I$8,MIN(MAX(ROUND(ROUND('Loonschijven_Tranches salariale'!$Q9*0.6,4)*Basisbedragen!$I$2,2),ROUND(Basisbedragen!$D$39*Basisbedragen!$I$2,2)),ROUND(ROUND(Basisbedragen!$D$28*0.6,4)*Basisbedragen!$I$2,2)),MIN(MAX(ROUND(ROUND('Loonschijven_Tranches salariale'!$Q9*0.6,4)*Basisbedragen!$I$7,2),ROUND(Basisbedragen!$D$39*Basisbedragen!$I$7,2)),ROUND(ROUND(Basisbedragen!$D$28*0.6,4)*Basisbedragen!$I$7,2))+Basisbedragen!$I$10) -> 56.23 | Q14: =MIN(MAX(ROUND(ROUND('Loonschijven_Tranches salariale'!$Q9*0.6,4)*Basisbedragen!$I$2,2),ROUND(Basisbedragen!$D$40*Basisbedragen!$I$2,2)),ROUND(ROUND(Basisbedragen!$D$29*0.6,4)*Basisbedragen!$I$2,2)) -> 51.12 | S14: =$S$12 -> 42.37 | T14: =$T$12 -> 29.85
A15: =A14+1 -> 3 | C15: =IF(MIN(MAX(ROUND(ROUND('Loonschijven_Tranches salariale'!$Q10*0.65,4)*Basisbedragen!$I$7,2),ROUND(Basisbedragen!$D$34*Basisbedragen!$I$7,2)),ROUND(ROUND(Basisbedragen!$D$27*0.65,4)*Basisbedragen!$I$7,2))<= Basisbedragen!$I$8,MIN(MAX(ROUND(ROUND('Loonschijven_Tranches salariale'!$Q10*0.65,4)*Basisbedragen!$I$2,2),ROUND(Basisbedragen!$D$34*Basisbedragen!$I$2,2)),ROUND(ROUND(Basisbedragen!$D$27*0.65,4)*Basisbedragen!$I$2,2)),MIN(MAX(ROUND(ROUND('Loonschijven_Tranches salariale'!$Q10*0.65,4)*Basisbedragen!$I$7,2),ROUND(Basisbedragen!$D$34*Basisbedragen!$I$7,2)),ROUND(ROUND(Basisbedragen!$D$27*0.65,4)*Basisbedragen!$I$7,2))+Basisbedragen!$I$10) -> 78.09 | D15: =IF(MIN(MAX(ROUND(ROUND('Loonschijven_Tranches salariale'!$Q10*0.6,4)*Basisbedragen!$I$7,2),ROUND(Basisbedragen!$D$34*Basisbedragen!$I$7,2)),ROUND(ROUND(Basisbedragen!$D$28*0.6,4)*Basisbedragen!$I$7,2))<= Basisbedragen!$I$8,MIN(MAX(ROUND(ROUND('Loonschijven_Tranches salariale'!$Q10*0.6,4)*Basisbedragen!$I$2,2),ROUND(Basisbedragen!$D$34*Basisbedragen!$I$2,2)),ROUND(ROUND(Basisbedragen!$D$28*0.6,4)*Basisbedragen!$I$2,2)),MIN(MAX(ROUND(ROUND('Loonschijven_Tranches salariale'!$Q10*0.6,4)*Basisbedragen!$I$7,2),ROUND(Basisbedragen!$D$34*Basisbedragen!$I$7,2)),ROUND(ROUND(Basisbedragen!$D$28*0.6,4)*Basisbedragen!$I$7,2))+Basisbedragen!$I$10) -> 78.09 | E15: =MIN(MAX(ROUND(ROUND('Loonschijven_Tranches salariale'!$Q10*0.6,4)*Basisbedragen!$I$2,2),ROUND(Basisbedragen!$D$35*Basisbedragen!$I$2,2)),ROUND(ROUND(Basisbedragen!$D$29*0.6,4)*Basisbedragen!$I$2,2)) -> 70.99 | G15: =$E$12 -> 70.99 | I15: =IF(MIN(MAX(ROUND(ROUND('Loonschijven_Tranches salariale'!$Q10*0.65,4)*Basisbedragen!$I$7,2),ROUND(Basisbedragen!$D$36*Basisbedragen!$I$7,2)),ROUND(ROUND(Basisbedragen!$D$27*0.65,4)*Basisbedragen!$I$7,2))<= Basisbedragen!$I$8,MIN(MAX(ROUND(ROUND('Loonschijven_Tranches salariale'!$Q10*0.65,4)*Basisbedragen!$I$2,2),ROUND(Basisbedragen!$D$36*Basisbedragen!$I$2,2)),ROUND(ROUND(Basisbedragen!$D$27*0.65,4)*Basisbedragen!$I$2,2)),MIN(MAX(ROUND(ROUND('Loonschijven_Tranches salariale'!$Q10*0.65,4)*Basisbedragen!$I$7,2),ROUND(Basisbedragen!$D$36*Basisbedragen!$I$7,2)),ROUND(ROUND(Basisbedragen!$D$27*0.65,4)*Basisbedragen!$I$7,2))+Basisbedragen!$I$10) -> 63.29 | J15: =IF(MIN(MAX(ROUND(ROUND('Loonschijven_Tranches salariale'!$Q10*0.6,4)*Basisbedragen!$I$7,2),ROUND(Basisbedragen!$D$36*Basisbedragen!$I$7,2)),ROUND(ROUND(Basisbedragen!$D$28*0.6,4)*Basisbedragen!$I$7,2))<= Basisbedragen!$I$8,MIN(MAX(ROUND(ROUND('Loonschijven_Tranches salariale'!$Q10*0.6,4)*Basisbedragen!$I$2,2),ROUND(Basisbedragen!$D$36*Basisbedragen!$I$2,2)),ROUND(ROUND(Basisbedragen!$D$28*0.6,4)*Basisbedragen!$I$2,2)),MIN(MAX(ROUND(ROUND('Loonschijven_Tranches salariale'!$Q10*0.6,4)*Basisbedragen!$I$7,2),ROUND(Basisbedragen!$D$36*Basisbedragen!$I$7,2)),ROUND(ROUND(Basisbedragen!$D$28*0.6,4)*Basisbedragen!$I$7,2))+Basisbedragen!$I$10) -> 63.29 | K15: =MIN(MAX(ROUND(ROUND('Loonschijven_Tranches salariale'!$Q10*0.6,4)*Basisbedragen!$I$2,2),ROUND(Basisbedragen!$D$37*Basisbedragen!$I$2,2)),ROUND(ROUND(Basisbedragen!$D$29*0.6,4)*Basisbedragen!$I$2,2)) -> 57.53 | M15: =$K$12 -> 57.53 | O15: =IF(MIN(MAX(ROUND(ROUND('Loonschijven_Tranches salariale'!$Q10*0.65,4)*Basisbedragen!$I$7,2),ROUND(Basisbedragen!$D$38*Basisbedragen!$I$7,2)),ROUND(ROUND(Basisbedragen!$D$27*0.65,4)*Basisbedragen!$I$7,2))<= Basisbedragen!$I$8,MIN(MAX(ROUND(ROUND('Loonschijven_Tranches salariale'!$Q10*0.65,4)*Basisbedragen!$I$2,2),ROUND(Basisbedragen!$D$38*Basisbedragen!$I$2,2)),ROUND(ROUND(Basisbedragen!$D$27*0.65,4)*Basisbedragen!$I$2,2)),MIN(MAX(ROUND(ROUND('Loonschijven_Tranches salariale'!$Q10*0.65,4)*Basisbedragen!$I$7,2),ROUND(Basisbedragen!$D$38*Basisbedragen!$I$7,2)),ROUND(ROUND(Basisbedragen!$D$27*0.65,4)*Basisbedragen!$I$7,2))+Basisbedragen!$I$10) -> 60.92 | P15: =IF(MIN(MAX(ROUND(ROUND('Loonschijven_Tranches salariale'!$Q10*0.6,4)*Basisbedragen!$I$7,2),ROUND(Basisbedragen!$D$39*Basisbedragen!$I$7,2)),ROUND(ROUND(Basisbedragen!$D$28*0.6,4)*Basisbedragen!$I$7,2))<= Basisbedragen!$I$8,MIN(MAX(ROUND(ROUND('Loonschijven_Tranches salariale'!$Q10*0.6,4)*Basisbedragen!$I$2,2),ROUND(Basisbedragen!$D$39*Basisbedragen!$I$2,2)),ROUND(ROUND(Basisbedragen!$D$28*0.6,4)*Basisbedragen!$I$2,2)),MIN(MAX(ROUND(ROUND('Loonschijven_Tranches salariale'!$Q10*0.6,4)*Basisbedragen!$I$7,2),ROUND(Basisbedragen!$D$39*Basisbedragen!$I$7,2)),ROUND(ROUND(Basisbedragen!$D$28*0.6,4)*Basisbedragen!$I$7,2))+Basisbedragen!$I$10) -> 56.23 | Q15: =MIN(MAX(ROUND(ROUND('Loonschijven_Tranches salariale'!$Q10*0.6,4)*Basisbedragen!$I$2,2),ROUND(Basisbedragen!$D$40*Basisbedragen!$I$2,2)),ROUND(ROUND(Basisbedragen!$D$29*0.6,4)*Basisbedragen!$I$2,2)) -> 51.12 | S15: =$S$12 -> 42.37 | T15: =$T$12 -> 29.85
A16: =A15+1 -> 4 | C16: =IF(MIN(MAX(ROUND(ROUND('Loonschijven_Tranches salariale'!$Q11*0.65,4)*Basisbedragen!$I$7,2),ROUND(Basisbedragen!$D$34*Basisbedragen!$I$7,2)),ROUND(ROUND(Basisbedragen!$D$27*0.65,4)*Basisbedragen!$I$7,2))<= Basisbedragen!$I$8,MIN(MAX(ROUND(ROUND('Loonschijven_Tranches salariale'!$Q11*0.65,4)*Basisbedragen!$I$2,2),ROUND(Basisbedragen!$D$34*Basisbedragen!$I$2,2)),ROUND(ROUND(Basisbedragen!$D$27*0.65,4)*Basisbedragen!$I$2,2)),MIN(MAX(ROUND(ROUND('Loonschijven_Tranches salariale'!$Q11*0.65,4)*Basisbedragen!$I$7,2),ROUND(Basisbedragen!$D$34*Basisbedragen!$I$7,2)),ROUND(ROUND(Basisbedragen!$D$27*0.65,4)*Basisbedragen!$I$7,2))+Basisbedragen!$I$10) -> 78.09 | D16: =IF(MIN(MAX(ROUND(ROUND('Loonschijven_Tranches salariale'!$Q11*0.6,4)*Basisbedragen!$I$7,2),ROUND(Basisbedragen!$D$34*Basisbedragen!$I$7,2)),ROUND(ROUND(Basisbedragen!$D$28*0.6,4)*Basisbedragen!$I$7,2))<= Basisbedragen!$I$8,MIN(MAX(ROUND(ROUND('Loonschijven_Tranches salariale'!$Q11*0.6,4)*Basisbedragen!$I$2,2),ROUND(Basisbedragen!$D$34*Basisbedragen!$I$2,2)),ROUND(ROUND(Basisbedragen!$D$28*0.6,4)*Basisbedragen!$I$2,2)),MIN(MAX(ROUND(ROUND('Loonschijven_Tranches salariale'!$Q11*0.6,4)*Basisbedragen!$I$7,2),ROUND(Basisbedragen!$D$34*Basisbedragen!$I$7,2)),ROUND(ROUND(Basisbedragen!$D$28*0.6,4)*Basisbedragen!$I$7,2))+Basisbedragen!$I$10) -> 78.09 | E16: =MIN(MAX(ROUND(ROUND('Loonschijven_Tranches salariale'!$Q11*0.6,4)*Basisbedragen!$I$2,2),ROUND(Basisbedragen!$D$35*Basisbedragen!$I$2,2)),ROUND(ROUND(Basisbedragen!$D$29*0.6,4)*Basisbedragen!$I$2,2)) -> 70.99 | G16: =$E$12 -> 70.99 | I16: =IF(MIN(MAX(ROUND(ROUND('Loonschijven_Tranches salariale'!$Q11*0.65,4)*Basisbedragen!$I$7,2),ROUND(Basisbedragen!$D$36*Basisbedragen!$I$7,2)),ROUND(ROUND(Basisbedragen!$D$27*0.65,4)*Basisbedragen!$I$7,2))<= Basisbedragen!$I$8,MIN(MAX(ROUND(ROUND('Loonschijven_Tranches salariale'!$Q11*0.65,4)*Basisbedragen!$I$2,2),ROUND(Basisbedragen!$D$36*Basisbedragen!$I$2,2)),ROUND(ROUND(Basisbedragen!$D$27*0.65,4)*Basisbedragen!$I$2,2)),MIN(MAX(ROUND(ROUND('Loonschijven_Tranches salariale'!$Q11*0.65,4)*Basisbedragen!$I$7,2),ROUND(Basisbedragen!$D$36*Basisbedragen!$I$7,2)),ROUND(ROUND(Basisbedragen!$D$27*0.65,4)*Basisbedragen!$I$7,2))+Basisbedragen!$I$10) -> 63.29 | J16: =IF(MIN(MAX(ROUND(ROUND('Loonschijven_Tranches salariale'!$Q11*0.6,4)*Basisbedragen!$I$7,2),ROUND(Basisbedragen!$D$36*Basisbedragen!$I$7,2)),ROUND(ROUND(Basisbedragen!$D$28*0.6,4)*Basisbedragen!$I$7,2))<= Basisbedragen!$I$8,MIN(MAX(ROUND(ROUND('Loonschijven_Tranches salariale'!$Q11*0.6,4)*Basisbedragen!$I$2,2),ROUND(Basisbedragen!$D$36*Basisbedragen!$I$2,2)),ROUND(ROUND(Basisbedragen!$D$28*0.6,4)*Basisbedragen!$I$2,2)),MIN(MAX(ROUND(ROUND('Loonschijven_Tranches salariale'!$Q11*0.6,4)*Basisbedragen!$I$7,2),ROUND(Basisbedragen!$D$36*Basisbedragen!$I$7,2)),ROUND(ROUND(Basisbedragen!$D$28*0.6,4)*Basisbedragen!$I$7,2))+Basisbedragen!$I$10) -> 63.29 | K16: =MIN(MAX(ROUND(ROUND('Loonschijven_Tranches salariale'!$Q11*0.6,4)*Basisbedragen!$I$2,2),ROUND(Basisbedragen!$D$37*Basisbedragen!$I$2,2)),ROUND(ROUND(Basisbedragen!$D$29*0.6,4)*Basisbedragen!$I$2,2)) -> 57.53 | M16: =$K$12 -> 57.53 | O16: =IF(MIN(MAX(ROUND(ROUND('Loonschijven_Tranches salariale'!$Q11*0.65,4)*Basisbedragen!$I$7,2),ROUND(Basisbedragen!$D$38*Basisbedragen!$I$7,2)),ROUND(ROUND(Basisbedragen!$D$27*0.65,4)*Basisbedragen!$I$7,2))<= Basisbedragen!$I$8,MIN(MAX(ROUND(ROUND('Loonschijven_Tranches salariale'!$Q11*0.65,4)*Basisbedragen!$I$2,2),ROUND(Basisbedragen!$D$38*Basisbedragen!$I$2,2)),ROUND(ROUND(Basisbedragen!$D$27*0.65,4)*Basisbedragen!$I$2,2)),MIN(MAX(ROUND(ROUND('Loonschijven_Tranches salariale'!$Q11*0.65,4)*Basisbedragen!$I$7,2),ROUND(Basisbedragen!$D$38*Basisbedragen!$I$7,2)),ROUND(ROUND(Basisbedragen!$D$27*0.65,4)*Basisbedragen!$I$7,2))+Basisbedragen!$I$10) -> 60.92 | P16: =IF(MIN(MAX(ROUND(ROUND('Loonschijven_Tranches salariale'!$Q11*0.6,4)*Basisbedragen!$I$7,2),ROUND(Basisbedragen!$D$39*Basisbedragen!$I$7,2)),ROUND(ROUND(Basisbedragen!$D$28*0.6,4)*Basisbedragen!$I$7,2))<= Basisbedragen!$I$8,MIN(MAX(ROUND(ROUND('Loonschijven_Tranches salariale'!$Q11*0.6,4)*Basisbedragen!$I$2,2),ROUND(Basisbedragen!$D$39*Basisbedragen!$I$2,2)),ROUND(ROUND(Basisbedragen!$D$28*0.6,4)*Basisbedragen!$I$2,2)),MIN(MAX(ROUND(ROUND('Loonschijven_Tranches salariale'!$Q11*0.6,4)*Basisbedragen!$I$7,2),ROUND(Basisbedragen!$D$39*Basisbedragen!$I$7,2)),ROUND(ROUND(Basisbedragen!$D$28*0.6,4)*Basisbedragen!$I$7,2))+Basisbedragen!$I$10) -> 56.23 | Q16: =MIN(MAX(ROUND(ROUND('Loonschijven_Tranches salariale'!$Q11*0.6,4)*Basisbedragen!$I$2,2),ROUND(Basisbedragen!$D$40*Basisbedragen!$I$2,2)),ROUND(ROUND(Basisbedragen!$D$29*0.6,4)*Basisbedragen!$I$2,2)) -> 51.12 | S16: =$S$12 -> 42.37 | T16: =$T$12 -> 29.85
A17: =A16+1 -> 5 | C17: =IF(MIN(MAX(ROUND(ROUND('Loonschijven_Tranches salariale'!$Q12*0.65,4)*Basisbedragen!$I$7,2),ROUND(Basisbedragen!$D$34*Basisbedragen!$I$7,2)),ROUND(ROUND(Basisbedragen!$D$27*0.65,4)*Basisbedragen!$I$7,2))<= Basisbedragen!$I$8,MIN(MAX(ROUND(ROUND('Loonschijven_Tranches salariale'!$Q12*0.65,4)*Basisbedragen!$I$2,2),ROUND(Basisbedragen!$D$34*Basisbedragen!$I$2,2)),ROUND(ROUND(Basisbedragen!$D$27*0.65,4)*Basisbedragen!$I$2,2)),MIN(MAX(ROUND(ROUND('Loonschijven_Tranches salariale'!$Q12*0.65,4)*Basisbedragen!$I$7,2),ROUND(Basisbedragen!$D$34*Basisbedragen!$I$7,2)),ROUND(ROUND(Basisbedragen!$D$27*0.65,4)*Basisbedragen!$I$7,2))+Basisbedragen!$I$10) -> 78.09 | D17: =IF(MIN(MAX(ROUND(ROUND('Loonschijven_Tranches salariale'!$Q12*0.6,4)*Basisbedragen!$I$7,2),ROUND(Basisbedragen!$D$34*Basisbedragen!$I$7,2)),ROUND(ROUND(Basisbedragen!$D$28*0.6,4)*Basisbedragen!$I$7,2))<= Basisbedragen!$I$8,MIN(MAX(ROUND(ROUND('Loonschijven_Tranches salariale'!$Q12*0.6,4)*Basisbedragen!$I$2,2),ROUND(Basisbedragen!$D$34*Basisbedragen!$I$2,2)),ROUND(ROUND(Basisbedragen!$D$28*0.6,4)*Basisbedragen!$I$2,2)),MIN(MAX(ROUND(ROUND('Loonschijven_Tranches salariale'!$Q12*0.6,4)*Basisbedragen!$I$7,2),ROUND(Basisbedragen!$D$34*Basisbedragen!$I$7,2)),ROUND(ROUND(Basisbedragen!$D$28*0.6,4)*Basisbedragen!$I$7,2))+Basisbedragen!$I$10) -> 78.09 | E17: =MIN(MAX(ROUND(ROUND('Loonschijven_Tranches salariale'!$Q12*0.6,4)*Basisbedragen!$I$2,2),ROUND(Basisbedragen!$D$35*Basisbedragen!$I$2,2)),ROUND(ROUND(Basisbedragen!$D$29*0.6,4)*Basisbedragen!$I$2,2)) -> 70.99 | G17: =$E$12 -> 70.99 | I17: =IF(MIN(MAX(ROUND(ROUND('Loonschijven_Tranches salariale'!$Q12*0.65,4)*Basisbedragen!$I$7,2),ROUND(Basisbedragen!$D$36*Basisbedragen!$I$7,2)),ROUND(ROUND(Basisbedragen!$D$27*0.65,4)*Basisbedragen!$I$7,2))<= Basisbedragen!$I$8,MIN(MAX(ROUND(ROUND('Loonschijven_Tranches salariale'!$Q12*0.65,4)*Basisbedragen!$I$2,2),ROUND(Basisbedragen!$D$36*Basisbedragen!$I$2,2)),ROUND(ROUND(Basisbedragen!$D$27*0.65,4)*Basisbedragen!$I$2,2)),MIN(MAX(ROUND(ROUND('Loonschijven_Tranches salariale'!$Q12*0.65,4)*Basisbedragen!$I$7,2),ROUND(Basisbedragen!$D$36*Basisbedragen!$I$7,2)),ROUND(ROUND(Basisbedragen!$D$27*0.65,4)*Basisbedragen!$I$7,2))+Basisbedragen!$I$10) -> 63.29 | J17: =IF(MIN(MAX(ROUND(ROUND('Loonschijven_Tranches salariale'!$Q12*0.6,4)*Basisbedragen!$I$7,2),ROUND(Basisbedragen!$D$36*Basisbedragen!$I$7,2)),ROUND(ROUND(Basisbedragen!$D$28*0.6,4)*Basisbedragen!$I$7,2))<= Basisbedragen!$I$8,MIN(MAX(ROUND(ROUND('Loonschijven_Tranches salariale'!$Q12*0.6,4)*Basisbedragen!$I$2,2),ROUND(Basisbedragen!$D$36*Basisbedragen!$I$2,2)),ROUND(ROUND(Basisbedragen!$D$28*0.6,4)*Basisbedragen!$I$2,2)),MIN(MAX(ROUND(ROUND('Loonschijven_Tranches salariale'!$Q12*0.6,4)*Basisbedragen!$I$7,2),ROUND(Basisbedragen!$D$36*Basisbedragen!$I$7,2)),ROUND(ROUND(Basisbedragen!$D$28*0.6,4)*Basisbedragen!$I$7,2))+Basisbedragen!$I$10) -> 63.29 | K17: =MIN(MAX(ROUND(ROUND('Loonschijven_Tranches salariale'!$Q12*0.6,4)*Basisbedragen!$I$2,2),ROUND(Basisbedragen!$D$37*Basisbedragen!$I$2,2)),ROUND(ROUND(Basisbedragen!$D$29*0.6,4)*Basisbedragen!$I$2,2)) -> 57.53 | M17: =$K$12 -> 57.53 | O17: =IF(MIN(MAX(ROUND(ROUND('Loonschijven_Tranches salariale'!$Q12*0.65,4)*Basisbedragen!$I$7,2),ROUND(Basisbedragen!$D$38*Basisbedragen!$I$7,2)),ROUND(ROUND(Basisbedragen!$D$27*0.65,4)*Basisbedragen!$I$7,2))<= Basisbedragen!$I$8,MIN(MAX(ROUND(ROUND('Loonschijven_Tranches salariale'!$Q12*0.65,4)*Basisbedragen!$I$2,2),ROUND(Basisbedragen!$D$38*Basisbedragen!$I$2,2)),ROUND(ROUND(Basisbedragen!$D$27*0.65,4)*Basisbedragen!$I$2,2)),MIN(MAX(ROUND(ROUND('Loonschijven_Tranches salariale'!$Q12*0.65,4)*Basisbedragen!$I$7,2),ROUND(Basisbedragen!$D$38*Basisbedragen!$I$7,2)),ROUND(ROUND(Basisbedragen!$D$27*0.65,4)*Basisbedragen!$I$7,2))+Basisbedragen!$I$10) -> 60.92 | P17: =IF(MIN(MAX(ROUND(ROUND('Loonschijven_Tranches salariale'!$Q12*0.6,4)*Basisbedragen!$I$7,2),ROUND(Basisbedragen!$D$39*Basisbedragen!$I$7,2)),ROUND(ROUND(Basisbedragen!$D$28*0.6,4)*Basisbedragen!$I$7,2))<= Basisbedragen!$I$8,MIN(MAX(ROUND(ROUND('Loonschijven_Tranches salariale'!$Q12*0.6,4)*Basisbedragen!$I$2,2),ROUND(Basisbedragen!$D$39*Basisbedragen!$I$2,2)),ROUND(ROUND(Basisbedragen!$D$28*0.6,4)*Basisbedragen!$I$2,2)),MIN(MAX(ROUND(ROUND('Loonschijven_Tranches salariale'!$Q12*0.6,4)*Basisbedragen!$I$7,2),ROUND(Basisbedragen!$D$39*Basisbedragen!$I$7,2)),ROUND(ROUND(Basisbedragen!$D$28*0.6,4)*Basisbedragen!$I$7,2))+Basisbedragen!$I$10) -> 56.23 | Q17: =MIN(MAX(ROUND(ROUND('Loonschijven_Tranches salariale'!$Q12*0.6,4)*Basisbedragen!$I$2,2),ROUND(Basisbedragen!$D$40*Basisbedragen!$I$2,2)),ROUND(ROUND(Basisbedragen!$D$29*0.6,4)*Basisbedragen!$I$2,2)) -> 51.12 | S17: =$S$12 -> 42.37 | T17: =$T$12 -> 29.85
A18: =A17+1 -> 6 | C18: =IF(MIN(MAX(ROUND(ROUND('Loonschijven_Tranches salariale'!$Q13*0.65,4)*Basisbedragen!$I$7,2),ROUND(Basisbedragen!$D$34*Basisbedragen!$I$7,2)),ROUND(ROUND(Basisbedragen!$D$27*0.65,4)*Basisbedragen!$I$7,2))<= Basisbedragen!$I$8,MIN(MAX(ROUND(ROUND('Loonschijven_Tranches salariale'!$Q13*0.65,4)*Basisbedragen!$I$2,2),ROUND(Basisbedragen!$D$34*Basisbedragen!$I$2,2)),ROUND(ROUND(Basisbedragen!$D$27*0.65,4)*Basisbedragen!$I$2,2)),MIN(MAX(ROUND(ROUND('Loonschijven_Tranches salariale'!$Q13*0.65,4)*Basisbedragen!$I$7,2),ROUND(Basisbedragen!$D$34*Basisbedragen!$I$7,2)),ROUND(ROUND(Basisbedragen!$D$27*0.65,4)*Basisbedragen!$I$7,2))+Basisbedragen!$I$10) -> 78.09 | D18: =IF(MIN(MAX(ROUND(ROUND('Loonschijven_Tranches salariale'!$Q13*0.6,4)*Basisbedragen!$I$7,2),ROUND(Basisbedragen!$D$34*Basisbedragen!$I$7,2)),ROUND(ROUND(Basisbedragen!$D$28*0.6,4)*Basisbedragen!$I$7,2))<= Basisbedragen!$I$8,MIN(MAX(ROUND(ROUND('Loonschijven_Tranches salariale'!$Q13*0.6,4)*Basisbedragen!$I$2,2),ROUND(Basisbedragen!$D$34*Basisbedragen!$I$2,2)),ROUND(ROUND(Basisbedragen!$D$28*0.6,4)*Basisbedragen!$I$2,2)),MIN(MAX(ROUND(ROUND('Loonschijven_Tranches salariale'!$Q13*0.6,4)*Basisbedragen!$I$7,2),ROUND(Basisbedragen!$D$34*Basisbedragen!$I$7,2)),ROUND(ROUND(Basisbedragen!$D$28*0.6,4)*Basisbedragen!$I$7,2))+Basisbedragen!$I$10) -> 78.09 | E18: =MIN(MAX(ROUND(ROUND('Loonschijven_Tranches salariale'!$Q13*0.6,4)*Basisbedragen!$I$2,2),ROUND(Basisbedragen!$D$35*Basisbedragen!$I$2,2)),ROUND(ROUND(Basisbedragen!$D$29*0.6,4)*Basisbedragen!$I$2,2)) -> 70.99 | G18: =$E$12 -> 70.99 | I18: =IF(MIN(MAX(ROUND(ROUND('Loonschijven_Tranches salariale'!$Q13*0.65,4)*Basisbedragen!$I$7,2),ROUND(Basisbedragen!$D$36*Basisbedragen!$I$7,2)),ROUND(ROUND(Basisbedragen!$D$27*0.65,4)*Basisbedragen!$I$7,2))<= Basisbedragen!$I$8,MIN(MAX(ROUND(ROUND('Loonschijven_Tranches salariale'!$Q13*0.65,4)*Basisbedragen!$I$2,2),ROUND(Basisbedragen!$D$36*Basisbedragen!$I$2,2)),ROUND(ROUND(Basisbedragen!$D$27*0.65,4)*Basisbedragen!$I$2,2)),MIN(MAX(ROUND(ROUND('Loonschijven_Tranches salariale'!$Q13*0.65,4)*Basisbedragen!$I$7,2),ROUND(Basisbedragen!$D$36*Basisbedragen!$I$7,2)),ROUND(ROUND(Basisbedragen!$D$27*0.65,4)*Basisbedragen!$I$7,2))+Basisbedragen!$I$10) -> 63.29 | J18: =IF(MIN(MAX(ROUND(ROUND('Loonschijven_Tranches salariale'!$Q13*0.6,4)*Basisbedragen!$I$7,2),ROUND(Basisbedragen!$D$36*Basisbedragen!$I$7,2)),ROUND(ROUND(Basisbedragen!$D$28*0.6,4)*Basisbedragen!$I$7,2))<= Basisbedragen!$I$8,MIN(MAX(ROUND(ROUND('Loonschijven_Tranches salariale'!$Q13*0.6,4)*Basisbedragen!$I$2,2),ROUND(Basisbedragen!$D$36*Basisbedragen!$I$2,2)),ROUND(ROUND(Basisbedragen!$D$28*0.6,4)*Basisbedragen!$I$2,2)),MIN(MAX(ROUND(ROUND('Loonschijven_Tranches salariale'!$Q13*0.6,4)*Basisbedragen!$I$7,2),ROUND(Basisbedragen!$D$36*Basisbedragen!$I$7,2)),ROUND(ROUND(Basisbedragen!$D$28*0.6,4)*Basisbedragen!$I$7,2))+Basisbedragen!$I$10) -> 63.29 | K18: =MIN(MAX(ROUND(ROUND('Loonschijven_Tranches salariale'!$Q13*0.6,4)*Basisbedragen!$I$2,2),ROUND(Basisbedragen!$D$37*Basisbedragen!$I$2,2)),ROUND(ROUND(Basisbedragen!$D$29*0.6,4)*Basisbedragen!$I$2,2)) -> 57.53 | M18: =$K$12 -> 57.53 | O18: =IF(MIN(MAX(ROUND(ROUND('Loonschijven_Tranches salariale'!$Q13*0.65,4)*Basisbedragen!$I$7,2),ROUND(Basisbedragen!$D$38*Basisbedragen!$I$7,2)),ROUND(ROUND(Basisbedragen!$D$27*0.65,4)*Basisbedragen!$I$7,2))<= Basisbedragen!$I$8,MIN(MAX(ROUND(ROUND('Loonschijven_Tranches salariale'!$Q13*0.65,4)*Basisbedragen!$I$2,2),ROUND(Basisbedragen!$D$38*Basisbedragen!$I$2,2)),ROUND(ROUND(Basisbedragen!$D$27*0.65,4)*Basisbedragen!$I$2,2)),MIN(MAX(ROUND(ROUND('Loonschijven_Tranches salariale'!$Q13*0.65,4)*Basisbedragen!$I$7,2),ROUND(Basisbedragen!$D$38*Basisbedragen!$I$7,2)),ROUND(ROUND(Basisbedragen!$D$27*0.65,4)*Basisbedragen!$I$7,2))+Basisbedragen!$I$10) -> 60.92 | P18: =IF(MIN(MAX(ROUND(ROUND('Loonschijven_Tranches salariale'!$Q13*0.6,4)*Basisbedragen!$I$7,2),ROUND(Basisbedragen!$D$39*Basisbedragen!$I$7,2)),ROUND(ROUND(Basisbedragen!$D$28*0.6,4)*Basisbedragen!$I$7,2))<= Basisbedragen!$I$8,MIN(MAX(ROUND(ROUND('Loonschijven_Tranches salariale'!$Q13*0.6,4)*Basisbedragen!$I$2,2),ROUND(Basisbedragen!$D$39*Basisbedragen!$I$2,2)),ROUND(ROUND(Basisbedragen!$D$28*0.6,4)*Basisbedragen!$I$2,2)),MIN(MAX(ROUND(ROUND('Loonschijven_Tranches salariale'!$Q13*0.6,4)*Basisbedragen!$I$7,2),ROUND(Basisbedragen!$D$39*Basisbedragen!$I$7,2)),ROUND(ROUND(Basisbedragen!$D$28*0.6,4)*Basisbedragen!$I$7,2))+Basisbedragen!$I$10) -> 56.23 | Q18: =MIN(MAX(ROUND(ROUND('Loonschijven_Tranches salariale'!$Q13*0.6,4)*Basisbedragen!$I$2,2),ROUND(Basisbedragen!$D$40*Basisbedragen!$I$2,2)),ROUND(ROUND(Basisbedragen!$D$29*0.6,4)*Basisbedragen!$I$2,2)) -> 51.12 | S18: =$S$12 -> 42.37 | T18: =$T$12 -> 29.85
A19: =A18+1 -> 7 | C19: =IF(MIN(MAX(ROUND(ROUND('Loonschijven_Tranches salariale'!$Q14*0.65,4)*Basisbedragen!$I$7,2),ROUND(Basisbedragen!$D$34*Basisbedragen!$I$7,2)),ROUND(ROUND(Basisbedragen!$D$27*0.65,4)*Basisbedragen!$I$7,2))<= Basisbedragen!$I$8,MIN(MAX(ROUND(ROUND('Loonschijven_Tranches salariale'!$Q14*0.65,4)*Basisbedragen!$I$2,2),ROUND(Basisbedragen!$D$34*Basisbedragen!$I$2,2)),ROUND(ROUND(Basisbedragen!$D$27*0.65,4)*Basisbedragen!$I$2,2)),MIN(MAX(ROUND(ROUND('Loonschijven_Tranches salariale'!$Q14*0.65,4)*Basisbedragen!$I$7,2),ROUND(Basisbedragen!$D$34*Basisbedragen!$I$7,2)),ROUND(ROUND(Basisbedragen!$D$27*0.65,4)*Basisbedragen!$I$7,2))+Basisbedragen!$I$10) -> 78.09 | D19: =IF(MIN(MAX(ROUND(ROUND('Loonschijven_Tranches salariale'!$Q14*0.6,4)*Basisbedragen!$I$7,2),ROUND(Basisbedragen!$D$34*Basisbedragen!$I$7,2)),ROUND(ROUND(Basisbedragen!$D$28*0.6,4)*Basisbedragen!$I$7,2))<= Basisbedragen!$I$8,MIN(MAX(ROUND(ROUND('Loonschijven_Tranches salariale'!$Q14*0.6,4)*Basisbedragen!$I$2,2),ROUND(Basisbedragen!$D$34*Basisbedragen!$I$2,2)),ROUND(ROUND(Basisbedragen!$D$28*0.6,4)*Basisbedragen!$I$2,2)),MIN(MAX(ROUND(ROUND('Loonschijven_Tranches salariale'!$Q14*0.6,4)*Basisbedragen!$I$7,2),ROUND(Basisbedragen!$D$34*Basisbedragen!$I$7,2)),ROUND(ROUND(Basisbedragen!$D$28*0.6,4)*Basisbedragen!$I$7,2))+Basisbedragen!$I$10) -> 78.09 | E19: =MIN(MAX(ROUND(ROUND('Loonschijven_Tranches salariale'!$Q14*0.6,4)*Basisbedragen!$I$2,2),ROUND(Basisbedragen!$D$35*Basisbedragen!$I$2,2)),ROUND(ROUND(Basisbedragen!$D$29*0.6,4)*Basisbedragen!$I$2,2)) -> 70.99 | G19: =$E$12 -> 70.99 | I19: =IF(MIN(MAX(ROUND(ROUND('Loonschijven_Tranches salariale'!$Q14*0.65,4)*Basisbedragen!$I$7,2),ROUND(Basisbedragen!$D$36*Basisbedragen!$I$7,2)),ROUND(ROUND(Basisbedragen!$D$27*0.65,4)*Basisbedragen!$I$7,2))<= Basisbedragen!$I$8,MIN(MAX(ROUND(ROUND('Loonschijven_Tranches salariale'!$Q14*0.65,4)*Basisbedragen!$I$2,2),ROUND(Basisbedragen!$D$36*Basisbedragen!$I$2,2)),ROUND(ROUND(Basisbedragen!$D$27*0.65,4)*Basisbedragen!$I$2,2)),MIN(MAX(ROUND(ROUND('Loonschijven_Tranches salariale'!$Q14*0.65,4)*Basisbedragen!$I$7,2),ROUND(Basisbedragen!$D$36*Basisbedragen!$I$7,2)),ROUND(ROUND(Basisbedragen!$D$27*0.65,4)*Basisbedragen!$I$7,2))+Basisbedragen!$I$10) -> 63.29 | J19: =IF(MIN(MAX(ROUND(ROUND('Loonschijven_Tranches salariale'!$Q14*0.6,4)*Basisbedragen!$I$7,2),ROUND(Basisbedragen!$D$36*Basisbedragen!$I$7,2)),ROUND(ROUND(Basisbedragen!$D$28*0.6,4)*Basisbedragen!$I$7,2))<= Basisbedragen!$I$8,MIN(MAX(ROUND(ROUND('Loonschijven_Tranches salariale'!$Q14*0.6,4)*Basisbedragen!$I$2,2),ROUND(Basisbedragen!$D$36*Basisbedragen!$I$2,2)),ROUND(ROUND(Basisbedragen!$D$28*0.6,4)*Basisbedragen!$I$2,2)),MIN(MAX(ROUND(ROUND('Loonschijven_Tranches salariale'!$Q14*0.6,4)*Basisbedragen!$I$7,2),ROUND(Basisbedragen!$D$36*Basisbedragen!$I$7,2)),ROUND(ROUND(Basisbedragen!$D$28*0.6,4)*Basisbedragen!$I$7,2))+Basisbedragen!$I$10) -> 63.29 | K19: =MIN(MAX(ROUND(ROUND('Loonschijven_Tranches salariale'!$Q14*0.6,4)*Basisbedragen!$I$2,2),ROUND(Basisbedragen!$D$37*Basisbedragen!$I$2,2)),ROUND(ROUND(Basisbedragen!$D$29*0.6,4)*Basisbedragen!$I$2,2)) -> 57.53 | M19: =$K$12 -> 57.53 | O19: =IF(MIN(MAX(ROUND(ROUND('Loonschijven_Tranches salariale'!$Q14*0.65,4)*Basisbedragen!$I$7,2),ROUND(Basisbedragen!$D$38*Basisbedragen!$I$7,2)),ROUND(ROUND(Basisbedragen!$D$27*0.65,4)*Basisbedragen!$I$7,2))<= Basisbedragen!$I$8,MIN(MAX(ROUND(ROUND('Loonschijven_Tranches salariale'!$Q14*0.65,4)*Basisbedragen!$I$2,2),ROUND(Basisbedragen!$D$38*Basisbedragen!$I$2,2)),ROUND(ROUND(Basisbedragen!$D$27*0.65,4)*Basisbedragen!$I$2,2)),MIN(MAX(ROUND(ROUND('Loonschijven_Tranches salariale'!$Q14*0.65,4)*Basisbedragen!$I$7,2),ROUND(Basisbedragen!$D$38*Basisbedragen!$I$7,2)),ROUND(ROUND(Basisbedragen!$D$27*0.65,4)*Basisbedragen!$I$7,2))+Basisbedragen!$I$10) -> 60.92 | P19: =IF(MIN(MAX(ROUND(ROUND('Loonschijven_Tranches salariale'!$Q14*0.6,4)*Basisbedragen!$I$7,2),ROUND(Basisbedragen!$D$39*Basisbedragen!$I$7,2)),ROUND(ROUND(Basisbedragen!$D$28*0.6,4)*Basisbedragen!$I$7,2))<= Basisbedragen!$I$8,MIN(MAX(ROUND(ROUND('Loonschijven_Tranches salariale'!$Q14*0.6,4)*Basisbedragen!$I$2,2),ROUND(Basisbedragen!$D$39*Basisbedragen!$I$2,2)),ROUND(ROUND(Basisbedragen!$D$28*0.6,4)*Basisbedragen!$I$2,2)),MIN(MAX(ROUND(ROUND('Loonschijven_Tranches salariale'!$Q14*0.6,4)*Basisbedragen!$I$7,2),ROUND(Basisbedragen!$D$39*Basisbedragen!$I$7,2)),ROUND(ROUND(Basisbedragen!$D$28*0.6,4)*Basisbedragen!$I$7,2))+Basisbedragen!$I$10) -> 56.23 | Q19: =MIN(MAX(ROUND(ROUND('Loonschijven_Tranches salariale'!$Q14*0.6,4)*Basisbedragen!$I$2,2),ROUND(Basisbedragen!$D$40*Basisbedragen!$I$2,2)),ROUND(ROUND(Basisbedragen!$D$29*0.6,4)*Basisbedragen!$I$2,2)) -> 51.12 | S19: =$S$12 -> 42.37 | T19: =$T$12 -> 29.85
A20: =A19+1 -> 8 | C20: =IF(MIN(MAX(ROUND(ROUND('Loonschijven_Tranches salariale'!$Q15*0.65,4)*Basisbedragen!$I$7,2),ROUND(Basisbedragen!$D$34*Basisbedragen!$I$7,2)),ROUND(ROUND(Basisbedragen!$D$27*0.65,4)*Basisbedragen!$I$7,2))<= Basisbedragen!$I$8,MIN(MAX(ROUND(ROUND('Loonschijven_Tranches salariale'!$Q15*0.65,4)*Basisbedragen!$I$2,2),ROUND(Basisbedragen!$D$34*Basisbedragen!$I$2,2)),ROUND(ROUND(Basisbedragen!$D$27*0.65,4)*Basisbedragen!$I$2,2)),MIN(MAX(ROUND(ROUND('Loonschijven_Tranches salariale'!$Q15*0.65,4)*Basisbedragen!$I$7,2),ROUND(Basisbedragen!$D$34*Basisbedragen!$I$7,2)),ROUND(ROUND(Basisbedragen!$D$27*0.65,4)*Basisbedragen!$I$7,2))+Basisbedragen!$I$10) -> 78.09 | D20: =IF(MIN(MAX(ROUND(ROUND('Loonschijven_Tranches salariale'!$Q15*0.6,4)*Basisbedragen!$I$7,2),ROUND(Basisbedragen!$D$34*Basisbedragen!$I$7,2)),ROUND(ROUND(Basisbedragen!$D$28*0.6,4)*Basisbedragen!$I$7,2))<= Basisbedragen!$I$8,MIN(MAX(ROUND(ROUND('Loonschijven_Tranches salariale'!$Q15*0.6,4)*Basisbedragen!$I$2,2),ROUND(Basisbedragen!$D$34*Basisbedragen!$I$2,2)),ROUND(ROUND(Basisbedragen!$D$28*0.6,4)*Basisbedragen!$I$2,2)),MIN(MAX(ROUND(ROUND('Loonschijven_Tranches salariale'!$Q15*0.6,4)*Basisbedragen!$I$7,2),ROUND(Basisbedragen!$D$34*Basisbedragen!$I$7,2)),ROUND(ROUND(Basisbedragen!$D$28*0.6,4)*Basisbedragen!$I$7,2))+Basisbedragen!$I$10) -> 78.09 | E20: =MIN(MAX(ROUND(ROUND('Loonschijven_Tranches salariale'!$Q15*0.6,4)*Basisbedragen!$I$2,2),ROUND(Basisbedragen!$D$35*Basisbedragen!$I$2,2)),ROUND(ROUND(Basisbedragen!$D$29*0.6,4)*Basisbedragen!$I$2,2)) -> 70.99 | G20: =$E$12 -> 70.99 | I20: =IF(MIN(MAX(ROUND(ROUND('Loonschijven_Tranches salariale'!$Q15*0.65,4)*Basisbedragen!$I$7,2),ROUND(Basisbedragen!$D$36*Basisbedragen!$I$7,2)),ROUND(ROUND(Basisbedragen!$D$27*0.65,4)*Basisbedragen!$I$7,2))<= Basisbedragen!$I$8,MIN(MAX(ROUND(ROUND('Loonschijven_Tranches salariale'!$Q15*0.65,4)*Basisbedragen!$I$2,2),ROUND(Basisbedragen!$D$36*Basisbedragen!$I$2,2)),ROUND(ROUND(Basisbedragen!$D$27*0.65,4)*Basisbedragen!$I$2,2)),MIN(MAX(ROUND(ROUND('Loonschijven_Tranches salariale'!$Q15*0.65,4)*Basisbedragen!$I$7,2),ROUND(Basisbedragen!$D$36*Basisbedragen!$I$7,2)),ROUND(ROUND(Basisbedragen!$D$27*0.65,4)*Basisbedragen!$I$7,2))+Basisbedragen!$I$10) -> 63.29 | J20: =IF(MIN(MAX(ROUND(ROUND('Loonschijven_Tranches salariale'!$Q15*0.6,4)*Basisbedragen!$I$7,2),ROUND(Basisbedragen!$D$36*Basisbedragen!$I$7,2)),ROUND(ROUND(Basisbedragen!$D$28*0.6,4)*Basisbedragen!$I$7,2))<= Basisbedragen!$I$8,MIN(MAX(ROUND(ROUND('Loonschijven_Tranches salariale'!$Q15*0.6,4)*Basisbedragen!$I$2,2),ROUND(Basisbedragen!$D$36*Basisbedragen!$I$2,2)),ROUND(ROUND(Basisbedragen!$D$28*0.6,4)*Basisbedragen!$I$2,2)),MIN(MAX(ROUND(ROUND('Loonschijven_Tranches salariale'!$Q15*0.6,4)*Basisbedragen!$I$7,2),ROUND(Basisbedragen!$D$36*Basisbedragen!$I$7,2)),ROUND(ROUND(Basisbedragen!$D$28*0.6,4)*Basisbedragen!$I$7,2))+Basisbedragen!$I$10) -> 63.29 | K20: =MIN(MAX(ROUND(ROUND('Loonschijven_Tranches salariale'!$Q15*0.6,4)*Basisbedragen!$I$2,2),ROUND(Basisbedragen!$D$37*Basisbedragen!$I$2,2)),ROUND(ROUND(Basisbedragen!$D$29*0.6,4)*Basisbedragen!$I$2,2)) -> 57.53 | M20: =$K$12 -> 57.53 | O20: =IF(MIN(MAX(ROUND(ROUND('Loonschijven_Tranches salariale'!$Q15*0.65,4)*Basisbedragen!$I$7,2),ROUND(Basisbedragen!$D$38*Basisbedragen!$I$7,2)),ROUND(ROUND(Basisbedragen!$D$27*0.65,4)*Basisbedragen!$I$7,2))<= Basisbedragen!$I$8,MIN(MAX(ROUND(ROUND('Loonschijven_Tranches salariale'!$Q15*0.65,4)*Basisbedragen!$I$2,2),ROUND(Basisbedragen!$D$38*Basisbedragen!$I$2,2)),ROUND(ROUND(Basisbedragen!$D$27*0.65,4)*Basisbedragen!$I$2,2)),MIN(MAX(ROUND(ROUND('Loonschijven_Tranches salariale'!$Q15*0.65,4)*Basisbedragen!$I$7,2),ROUND(Basisbedragen!$D$38*Basisbedragen!$I$7,2)),ROUND(ROUND(Basisbedragen!$D$27*0.65,4)*Basisbedragen!$I$7,2))+Basisbedragen!$I$10) -> 60.92 | P20: =IF(MIN(MAX(ROUND(ROUND('Loonschijven_Tranches salariale'!$Q15*0.6,4)*Basisbedragen!$I$7,2),ROUND(Basisbedragen!$D$39*Basisbedragen!$I$7,2)),ROUND(ROUND(Basisbedragen!$D$28*0.6,4)*Basisbedragen!$I$7,2))<= Basisbedragen!$I$8,MIN(MAX(ROUND(ROUND('Loonschijven_Tranches salariale'!$Q15*0.6,4)*Basisbedragen!$I$2,2),ROUND(Basisbedragen!$D$39*Basisbedragen!$I$2,2)),ROUND(ROUND(Basisbedragen!$D$28*0.6,4)*Basisbedragen!$I$2,2)),MIN(MAX(ROUND(ROUND('Loonschijven_Tranches salariale'!$Q15*0.6,4)*Basisbedragen!$I$7,2),ROUND(Basisbedragen!$D$39*Basisbedragen!$I$7,2)),ROUND(ROUND(Basisbedragen!$D$28*0.6,4)*Basisbedragen!$I$7,2))+Basisbedragen!$I$10) -> 56.23 | Q20: =MIN(MAX(ROUND(ROUND('Loonschijven_Tranches salariale'!$Q15*0.6,4)*Basisbedragen!$I$2,2),ROUND(Basisbedragen!$D$40*Basisbedragen!$I$2,2)),ROUND(ROUND(Basisbedragen!$D$29*0.6,4)*Basisbedragen!$I$2,2)) -> 51.12 | S20: =$S$12 -> 42.37 | T20: =$T$12 -> 29.85
A21: =A20+1 -> 9 | C21: =IF(MIN(MAX(ROUND(ROUND('Loonschijven_Tranches salariale'!$Q16*0.65,4)*Basisbedragen!$I$7,2),ROUND(Basisbedragen!$D$34*Basisbedragen!$I$7,2)),ROUND(ROUND(Basisbedragen!$D$27*0.65,4)*Basisbedragen!$I$7,2))<= Basisbedragen!$I$8,MIN(MAX(ROUND(ROUND('Loonschijven_Tranches salariale'!$Q16*0.65,4)*Basisbedragen!$I$2,2),ROUND(Basisbedragen!$D$34*Basisbedragen!$I$2,2)),ROUND(ROUND(Basisbedragen!$D$27*0.65,4)*Basisbedragen!$I$2,2)),MIN(MAX(ROUND(ROUND('Loonschijven_Tranches salariale'!$Q16*0.65,4)*Basisbedragen!$I$7,2),ROUND(Basisbedragen!$D$34*Basisbedragen!$I$7,2)),ROUND(ROUND(Basisbedragen!$D$27*0.65,4)*Basisbedragen!$I$7,2))+Basisbedragen!$I$10) -> 78.09 | D21: =IF(MIN(MAX(ROUND(ROUND('Loonschijven_Tranches salariale'!$Q16*0.6,4)*Basisbedragen!$I$7,2),ROUND(Basisbedragen!$D$34*Basisbedragen!$I$7,2)),ROUND(ROUND(Basisbedragen!$D$28*0.6,4)*Basisbedragen!$I$7,2))<= Basisbedragen!$I$8,MIN(MAX(ROUND(ROUND('Loonschijven_Tranches salariale'!$Q16*0.6,4)*Basisbedragen!$I$2,2),ROUND(Basisbedragen!$D$34*Basisbedragen!$I$2,2)),ROUND(ROUND(Basisbedragen!$D$28*0.6,4)*Basisbedragen!$I$2,2)),MIN(MAX(ROUND(ROUND('Loonschijven_Tranches salariale'!$Q16*0.6,4)*Basisbedragen!$I$7,2),ROUND(Basisbedragen!$D$34*Basisbedragen!$I$7,2)),ROUND(ROUND(Basisbedragen!$D$28*0.6,4)*Basisbedragen!$I$7,2))+Basisbedragen!$I$10) -> 78.09 | E21: =MIN(MAX(ROUND(ROUND('Loonschijven_Tranches salariale'!$Q16*0.6,4)*Basisbedragen!$I$2,2),ROUND(Basisbedragen!$D$35*Basisbedragen!$I$2,2)),ROUND(ROUND(Basisbedragen!$D$29*0.6,4)*Basisbedragen!$I$2,2)) -> 70.99 | G21: =$E$12 -> 70.99 | I21: =IF(MIN(MAX(ROUND(ROUND('Loonschijven_Tranches salariale'!$Q16*0.65,4)*Basisbedragen!$I$7,2),ROUND(Basisbedragen!$D$36*Basisbedragen!$I$7,2)),ROUND(ROUND(Basisbedragen!$D$27*0.65,4)*Basisbedragen!$I$7,2))<= Basisbedragen!$I$8,MIN(MAX(ROUND(ROUND('Loonschijven_Tranches salariale'!$Q16*0.65,4)*Basisbedragen!$I$2,2),ROUND(Basisbedragen!$D$36*Basisbedragen!$I$2,2)),ROUND(ROUND(Basisbedragen!$D$27*0.65,4)*Basisbedragen!$I$2,2)),MIN(MAX(ROUND(ROUND('Loonschijven_Tranches salariale'!$Q16*0.65,4)*Basisbedragen!$I$7,2),ROUND(Basisbedragen!$D$36*Basisbedragen!$I$7,2)),ROUND(ROUND(Basisbedragen!$D$27*0.65,4)*Basisbedragen!$I$7,2))+Basisbedragen!$I$10) -> 63.29 | J21: =IF(MIN(MAX(ROUND(ROUND('Loonschijven_Tranches salariale'!$Q16*0.6,4)*Basisbedragen!$I$7,2),ROUND(Basisbedragen!$D$36*Basisbedragen!$I$7,2)),ROUND(ROUND(Basisbedragen!$D$28*0.6,4)*Basisbedragen!$I$7,2))<= Basisbedragen!$I$8,MIN(MAX(ROUND(ROUND('Loonschijven_Tranches salariale'!$Q16*0.6,4)*Basisbedragen!$I$2,2),ROUND(Basisbedragen!$D$36*Basisbedragen!$I$2,2)),ROUND(ROUND(Basisbedragen!$D$28*0.6,4)*Basisbedragen!$I$2,2)),MIN(MAX(ROUND(ROUND('Loonschijven_Tranches salariale'!$Q16*0.6,4)*Basisbedragen!$I$7,2),ROUND(Basisbedragen!$D$36*Basisbedragen!$I$7,2)),ROUND(ROUND(Basisbedragen!$D$28*0.6,4)*Basisbedragen!$I$7,2))+Basisbedragen!$I$10) -> 63.29 | K21: =MIN(MAX(ROUND(ROUND('Loonschijven_Tranches salariale'!$Q16*0.6,4)*Basisbedragen!$I$2,2),ROUND(Basisbedragen!$D$37*Basisbedragen!$I$2,2)),ROUND(ROUND(Basisbedragen!$D$29*0.6,4)*Basisbedragen!$I$2,2)) -> 57.53 | M21: =$K$12 -> 57.53 | O21: =IF(MIN(MAX(ROUND(ROUND('Loonschijven_Tranches salariale'!$Q16*0.65,4)*Basisbedragen!$I$7,2),ROUND(Basisbedragen!$D$38*Basisbedragen!$I$7,2)),ROUND(ROUND(Basisbedragen!$D$27*0.65,4)*Basisbedragen!$I$7,2))<= Basisbedragen!$I$8,MIN(MAX(ROUND(ROUND('Loonschijven_Tranches salariale'!$Q16*0.65,4)*Basisbedragen!$I$2,2),ROUND(Basisbedragen!$D$38*Basisbedragen!$I$2,2)),ROUND(ROUND(Basisbedragen!$D$27*0.65,4)*Basisbedragen!$I$2,2)),MIN(MAX(ROUND(ROUND('Loonschijven_Tranches salariale'!$Q16*0.65,4)*Basisbedragen!$I$7,2),ROUND(Basisbedragen!$D$38*Basisbedragen!$I$7,2)),ROUND(ROUND(Basisbedragen!$D$27*0.65,4)*Basisbedragen!$I$7,2))+Basisbedragen!$I$10) -> 60.92 | P21: =IF(MIN(MAX(ROUND(ROUND('Loonschijven_Tranches salariale'!$Q16*0.6,4)*Basisbedragen!$I$7,2),ROUND(Basisbedragen!$D$39*Basisbedragen!$I$7,2)),ROUND(ROUND(Basisbedragen!$D$28*0.6,4)*Basisbedragen!$I$7,2))<= Basisbedragen!$I$8,MIN(MAX(ROUND(ROUND('Loonschijven_Tranches salariale'!$Q16*0.6,4)*Basisbedragen!$I$2,2),ROUND(Basisbedragen!$D$39*Basisbedragen!$I$2,2)),ROUND(ROUND(Basisbedragen!$D$28*0.6,4)*Basisbedragen!$I$2,2)),MIN(MAX(ROUND(ROUND('Loonschijven_Tranches salariale'!$Q16*0.6,4)*Basisbedragen!$I$7,2),ROUND(Basisbedragen!$D$39*Basisbedragen!$I$7,2)),ROUND(ROUND(Basisbedragen!$D$28*0.6,4)*Basisbedragen!$I$7,2))+Basisbedragen!$I$10) -> 56.23 | Q21: =MIN(MAX(ROUND(ROUND('Loonschijven_Tranches salariale'!$Q16*0.6,4)*Basisbedragen!$I$2,2),ROUND(Basisbedragen!$D$40*Basisbedragen!$I$2,2)),ROUND(ROUND(Basisbedragen!$D$29*0.6,4)*Basisbedragen!$I$2,2)) -> 51.12 | S21: =$S$12 -> 42.37 | T21: =$T$12 -> 29.85
A22: =A21+1 -> 10 | C22: =IF(MIN(MAX(ROUND(ROUND('Loonschijven_Tranches salariale'!$Q17*0.65,4)*Basisbedragen!$I$7,2),ROUND(Basisbedragen!$D$34*Basisbedragen!$I$7,2)),ROUND(ROUND(Basisbedragen!$D$27*0.65,4)*Basisbedragen!$I$7,2))<= Basisbedragen!$I$8,MIN(MAX(ROUND(ROUND('Loonschijven_Tranches salariale'!$Q17*0.65,4)*Basisbedragen!$I$2,2),ROUND(Basisbedragen!$D$34*Basisbedragen!$I$2,2)),ROUND(ROUND(Basisbedragen!$D$27*0.65,4)*Basisbedragen!$I$2,2)),MIN(MAX(ROUND(ROUND('Loonschijven_Tranches salariale'!$Q17*0.65,4)*Basisbedragen!$I$7,2),ROUND(Basisbedragen!$D$34*Basisbedragen!$I$7,2)),ROUND(ROUND(Basisbedragen!$D$27*0.65,4)*Basisbedragen!$I$7,2))+Basisbedragen!$I$10) -> 78.09 | D22: =IF(MIN(MAX(ROUND(ROUND('Loonschijven_Tranches salariale'!$Q17*0.6,4)*Basisbedragen!$I$7,2),ROUND(Basisbedragen!$D$34*Basisbedragen!$I$7,2)),ROUND(ROUND(Basisbedragen!$D$28*0.6,4)*Basisbedragen!$I$7,2))<= Basisbedragen!$I$8,MIN(MAX(ROUND(ROUND('Loonschijven_Tranches salariale'!$Q17*0.6,4)*Basisbedragen!$I$2,2),ROUND(Basisbedragen!$D$34*Basisbedragen!$I$2,2)),ROUND(ROUND(Basisbedragen!$D$28*0.6,4)*Basisbedragen!$I$2,2)),MIN(MAX(ROUND(ROUND('Loonschijven_Tranches salariale'!$Q17*0.6,4)*Basisbedragen!$I$7,2),ROUND(Basisbedragen!$D$34*Basisbedragen!$I$7,2)),ROUND(ROUND(Basisbedragen!$D$28*0.6,4)*Basisbedragen!$I$7,2))+Basisbedragen!$I$10) -> 78.09 | E22: =MIN(MAX(ROUND(ROUND('Loonschijven_Tranches salariale'!$Q17*0.6,4)*Basisbedragen!$I$2,2),ROUND(Basisbedragen!$D$35*Basisbedragen!$I$2,2)),ROUND(ROUND(Basisbedragen!$D$29*0.6,4)*Basisbedragen!$I$2,2)) -> 70.99 | G22: =$E$12 -> 70.99 | I22: =IF(MIN(MAX(ROUND(ROUND('Loonschijven_Tranches salariale'!$Q17*0.65,4)*Basisbedragen!$I$7,2),ROUND(Basisbedragen!$D$36*Basisbedragen!$I$7,2)),ROUND(ROUND(Basisbedragen!$D$27*0.65,4)*Basisbedragen!$I$7,2))<= Basisbedragen!$I$8,MIN(MAX(ROUND(ROUND('Loonschijven_Tranches salariale'!$Q17*0.65,4)*Basisbedragen!$I$2,2),ROUND(Basisbedragen!$D$36*Basisbedragen!$I$2,2)),ROUND(ROUND(Basisbedragen!$D$27*0.65,4)*Basisbedragen!$I$2,2)),MIN(MAX(ROUND(ROUND('Loonschijven_Tranches salariale'!$Q17*0.65,4)*Basisbedragen!$I$7,2),ROUND(Basisbedragen!$D$36*Basisbedragen!$I$7,2)),ROUND(ROUND(Basisbedragen!$D$27*0.65,4)*Basisbedragen!$I$7,2))+Basisbedragen!$I$10) -> 63.29 | J22: =IF(MIN(MAX(ROUND(ROUND('Loonschijven_Tranches salariale'!$Q17*0.6,4)*Basisbedragen!$I$7,2),ROUND(Basisbedragen!$D$36*Basisbedragen!$I$7,2)),ROUND(ROUND(Basisbedragen!$D$28*0.6,4)*Basisbedragen!$I$7,2))<= Basisbedragen!$I$8,MIN(MAX(ROUND(ROUND('Loonschijven_Tranches salariale'!$Q17*0.6,4)*Basisbedragen!$I$2,2),ROUND(Basisbedragen!$D$36*Basisbedragen!$I$2,2)),ROUND(ROUND(Basisbedragen!$D$28*0.6,4)*Basisbedragen!$I$2,2)),MIN(MAX(ROUND(ROUND('Loonschijven_Tranches salariale'!$Q17*0.6,4)*Basisbedragen!$I$7,2),ROUND(Basisbedragen!$D$36*Basisbedragen!$I$7,2)),ROUND(ROUND(Basisbedragen!$D$28*0.6,4)*Basisbedragen!$I$7,2))+Basisbedragen!$I$10) -> 63.29 | K22: =MIN(MAX(ROUND(ROUND('Loonschijven_Tranches salariale'!$Q17*0.6,4)*Basisbedragen!$I$2,2),ROUND(Basisbedragen!$D$37*Basisbedragen!$I$2,2)),ROUND(ROUND(Basisbedragen!$D$29*0.6,4)*Basisbedragen!$I$2,2)) -> 57.53 | M22: =$K$12 -> 57.53 | O22: =IF(MIN(MAX(ROUND(ROUND('Loonschijven_Tranches salariale'!$Q17*0.65,4)*Basisbedragen!$I$7,2),ROUND(Basisbedragen!$D$38*Basisbedragen!$I$7,2)),ROUND(ROUND(Basisbedragen!$D$27*0.65,4)*Basisbedragen!$I$7,2))<= Basisbedragen!$I$8,MIN(MAX(ROUND(ROUND('Loonschijven_Tranches salariale'!$Q17*0.65,4)*Basisbedragen!$I$2,2),ROUND(Basisbedragen!$D$38*Basisbedragen!$I$2,2)),ROUND(ROUND(Basisbedragen!$D$27*0.65,4)*Basisbedragen!$I$2,2)),MIN(MAX(ROUND(ROUND('Loonschijven_Tranches salariale'!$Q17*0.65,4)*Basisbedragen!$I$7,2),ROUND(Basisbedragen!$D$38*Basisbedragen!$I$7,2)),ROUND(ROUND(Basisbedragen!$D$27*0.65,4)*Basisbedragen!$I$7,2))+Basisbedragen!$I$10) -> 60.92 | P22: =IF(MIN(MAX(ROUND(ROUND('Loonschijven_Tranches salariale'!$Q17*0.6,4)*Basisbedragen!$I$7,2),ROUND(Basisbedragen!$D$39*Basisbedragen!$I$7,2)),ROUND(ROUND(Basisbedragen!$D$28*0.6,4)*Basisbedragen!$I$7,2))<= Basisbedragen!$I$8,MIN(MAX(ROUND(ROUND('Loonschijven_Tranches salariale'!$Q17*0.6,4)*Basisbedragen!$I$2,2),ROUND(Basisbedragen!$D$39*Basisbedragen!$I$2,2)),ROUND(ROUND(Basisbedragen!$D$28*0.6,4)*Basisbedragen!$I$2,2)),MIN(MAX(ROUND(ROUND('Loonschijven_Tranches salariale'!$Q17*0.6,4)*Basisbedragen!$I$7,2),ROUND(Basisbedragen!$D$39*Basisbedragen!$I$7,2)),ROUND(ROUND(Basisbedragen!$D$28*0.6,4)*Basisbedragen!$I$7,2))+Basisbedragen!$I$10) -> 56.23 | Q22: =MIN(MAX(ROUND(ROUND('Loonschijven_Tranches salariale'!$Q17*0.6,4)*Basisbedragen!$I$2,2),ROUND(Basisbedragen!$D$40*Basisbedragen!$I$2,2)),ROUND(ROUND(Basisbedragen!$D$29*0.6,4)*Basisbedragen!$I$2,2)) -> 51.12 | S22: =$S$12 -> 42.37 | T22: =$T$12 -> 29.85
A23: =A22+1 -> 11 | C23: =IF(MIN(MAX(ROUND(ROUND('Loonschijven_Tranches salariale'!$Q18*0.65,4)*Basisbedragen!$I$7,2),ROUND(Basisbedragen!$D$34*Basisbedragen!$I$7,2)),ROUND(ROUND(Basisbedragen!$D$27*0.65,4)*Basisbedragen!$I$7,2))<= Basisbedragen!$I$8,MIN(MAX(ROUND(ROUND('Loonschijven_Tranches salariale'!$Q18*0.65,4)*Basisbedragen!$I$2,2),ROUND(Basisbedragen!$D$34*Basisbedragen!$I$2,2)),ROUND(ROUND(Basisbedragen!$D$27*0.65,4)*Basisbedragen!$I$2,2)),MIN(MAX(ROUND(ROUND('Loonschijven_Tranches salariale'!$Q18*0.65,4)*Basisbedragen!$I$7,2),ROUND(Basisbedragen!$D$34*Basisbedragen!$I$7,2)),ROUND(ROUND(Basisbedragen!$D$27*0.65,4)*Basisbedragen!$I$7,2))+Basisbedragen!$I$10) -> 78.09 | D23: =IF(MIN(MAX(ROUND(ROUND('Loonschijven_Tranches salariale'!$Q18*0.6,4)*Basisbedragen!$I$7,2),ROUND(Basisbedragen!$D$34*Basisbedragen!$I$7,2)),ROUND(ROUND(Basisbedragen!$D$28*0.6,4)*Basisbedragen!$I$7,2))<= Basisbedragen!$I$8,MIN(MAX(ROUND(ROUND('Loonschijven_Tranches salariale'!$Q18*0.6,4)*Basisbedragen!$I$2,2),ROUND(Basisbedragen!$D$34*Basisbedragen!$I$2,2)),ROUND(ROUND(Basisbedragen!$D$28*0.6,4)*Basisbedragen!$I$2,2)),MIN(MAX(ROUND(ROUND('Loonschijven_Tranches salariale'!$Q18*0.6,4)*Basisbedragen!$I$7,2),ROUND(Basisbedragen!$D$34*Basisbedragen!$I$7,2)),ROUND(ROUND(Basisbedragen!$D$28*0.6,4)*Basisbedragen!$I$7,2))+Basisbedragen!$I$10) -> 78.09 | E23: =MIN(MAX(ROUND(ROUND('Loonschijven_Tranches salariale'!$Q18*0.6,4)*Basisbedragen!$I$2,2),ROUND(Basisbedragen!$D$35*Basisbedragen!$I$2,2)),ROUND(ROUND(Basisbedragen!$D$29*0.6,4)*Basisbedragen!$I$2,2)) -> 70.99 | G23: =$E$12 -> 70.99 | I23: =IF(MIN(MAX(ROUND(ROUND('Loonschijven_Tranches salariale'!$Q18*0.65,4)*Basisbedragen!$I$7,2),ROUND(Basisbedragen!$D$36*Basisbedragen!$I$7,2)),ROUND(ROUND(Basisbedragen!$D$27*0.65,4)*Basisbedragen!$I$7,2))<= Basisbedragen!$I$8,MIN(MAX(ROUND(ROUND('Loonschijven_Tranches salariale'!$Q18*0.65,4)*Basisbedragen!$I$2,2),ROUND(Basisbedragen!$D$36*Basisbedragen!$I$2,2)),ROUND(ROUND(Basisbedragen!$D$27*0.65,4)*Basisbedragen!$I$2,2)),MIN(MAX(ROUND(ROUND('Loonschijven_Tranches salariale'!$Q18*0.65,4)*Basisbedragen!$I$7,2),ROUND(Basisbedragen!$D$36*Basisbedragen!$I$7,2)),ROUND(ROUND(Basisbedragen!$D$27*0.65,4)*Basisbedragen!$I$7,2))+Basisbedragen!$I$10) -> 63.29 | J23: =IF(MIN(MAX(ROUND(ROUND('Loonschijven_Tranches salariale'!$Q18*0.6,4)*Basisbedragen!$I$7,2),ROUND(Basisbedragen!$D$36*Basisbedragen!$I$7,2)),ROUND(ROUND(Basisbedragen!$D$28*0.6,4)*Basisbedragen!$I$7,2))<= Basisbedragen!$I$8,MIN(MAX(ROUND(ROUND('Loonschijven_Tranches salariale'!$Q18*0.6,4)*Basisbedragen!$I$2,2),ROUND(Basisbedragen!$D$36*Basisbedragen!$I$2,2)),ROUND(ROUND(Basisbedragen!$D$28*0.6,4)*Basisbedragen!$I$2,2)),MIN(MAX(ROUND(ROUND('Loonschijven_Tranches salariale'!$Q18*0.6,4)*Basisbedragen!$I$7,2),ROUND(Basisbedragen!$D$36*Basisbedragen!$I$7,2)),ROUND(ROUND(Basisbedragen!$D$28*0.6,4)*Basisbedragen!$I$7,2))+Basisbedragen!$I$10) -> 63.29 | K23: =MIN(MAX(ROUND(ROUND('Loonschijven_Tranches salariale'!$Q18*0.6,4)*Basisbedragen!$I$2,2),ROUND(Basisbedragen!$D$37*Basisbedragen!$I$2,2)),ROUND(ROUND(Basisbedragen!$D$29*0.6,4)*Basisbedragen!$I$2,2)) -> 57.53 | M23: =$K$12 -> 57.53 | O23: =IF(MIN(MAX(ROUND(ROUND('Loonschijven_Tranches salariale'!$Q18*0.65,4)*Basisbedragen!$I$7,2),ROUND(Basisbedragen!$D$38*Basisbedragen!$I$7,2)),ROUND(ROUND(Basisbedragen!$D$27*0.65,4)*Basisbedragen!$I$7,2))<= Basisbedragen!$I$8,MIN(MAX(ROUND(ROUND('Loonschijven_Tranches salariale'!$Q18*0.65,4)*Basisbedragen!$I$2,2),ROUND(Basisbedragen!$D$38*Basisbedragen!$I$2,2)),ROUND(ROUND(Basisbedragen!$D$27*0.65,4)*Basisbedragen!$I$2,2)),MIN(MAX(ROUND(ROUND('Loonschijven_Tranches salariale'!$Q18*0.65,4)*Basisbedragen!$I$7,2),ROUND(Basisbedragen!$D$38*Basisbedragen!$I$7,2)),ROUND(ROUND(Basisbedragen!$D$27*0.65,4)*Basisbedragen!$I$7,2))+Basisbedragen!$I$10) -> 60.92 | P23: =IF(MIN(MAX(ROUND(ROUND('Loonschijven_Tranches salariale'!$Q18*0.6,4)*Basisbedragen!$I$7,2),ROUND(Basisbedragen!$D$39*Basisbedragen!$I$7,2)),ROUND(ROUND(Basisbedragen!$D$28*0.6,4)*Basisbedragen!$I$7,2))<= Basisbedragen!$I$8,MIN(MAX(ROUND(ROUND('Loonschijven_Tranches salariale'!$Q18*0.6,4)*Basisbedragen!$I$2,2),ROUND(Basisbedragen!$D$39*Basisbedragen!$I$2,2)),ROUND(ROUND(Basisbedragen!$D$28*0.6,4)*Basisbedragen!$I$2,2)),MIN(MAX(ROUND(ROUND('Loonschijven_Tranches salariale'!$Q18*0.6,4)*Basisbedragen!$I$7,2),ROUND(Basisbedragen!$D$39*Basisbedragen!$I$7,2)),ROUND(ROUND(Basisbedragen!$D$28*0.6,4)*Basisbedragen!$I$7,2))+Basisbedragen!$I$10) -> 56.23 | Q23: =MIN(MAX(ROUND(ROUND('Loonschijven_Tranches salariale'!$Q18*0.6,4)*Basisbedragen!$I$2,2),ROUND(Basisbedragen!$D$40*Basisbedragen!$I$2,2)),ROUND(ROUND(Basisbedragen!$D$29*0.6,4)*Basisbedragen!$I$2,2)) -> 51.12 | S23: =$S$12 -> 42.37 | T23: =$T$12 -> 29.85
A24: =A23+1 -> 12 | C24: =IF(MIN(MAX(ROUND(ROUND('Loonschijven_Tranches salariale'!$Q19*0.65,4)*Basisbedragen!$I$7,2),ROUND(Basisbedragen!$D$34*Basisbedragen!$I$7,2)),ROUND(ROUND(Basisbedragen!$D$27*0.65,4)*Basisbedragen!$I$7,2))<= Basisbedragen!$I$8,MIN(MAX(ROUND(ROUND('Loonschijven_Tranches salariale'!$Q19*0.65,4)*Basisbedragen!$I$2,2),ROUND(Basisbedragen!$D$34*Basisbedragen!$I$2,2)),ROUND(ROUND(Basisbedragen!$D$27*0.65,4)*Basisbedragen!$I$2,2)),MIN(MAX(ROUND(ROUND('Loonschijven_Tranches salariale'!$Q19*0.65,4)*Basisbedragen!$I$7,2),ROUND(Basisbedragen!$D$34*Basisbedragen!$I$7,2)),ROUND(ROUND(Basisbedragen!$D$27*0.65,4)*Basisbedragen!$I$7,2))+Basisbedragen!$I$10) -> 78.09 | D24: =IF(MIN(MAX(ROUND(ROUND('Loonschijven_Tranches salariale'!$Q19*0.6,4)*Basisbedragen!$I$7,2),ROUND(Basisbedragen!$D$34*Basisbedragen!$I$7,2)),ROUND(ROUND(Basisbedragen!$D$28*0.6,4)*Basisbedragen!$I$7,2))<= Basisbedragen!$I$8,MIN(MAX(ROUND(ROUND('Loonschijven_Tranches salariale'!$Q19*0.6,4)*Basisbedragen!$I$2,2),ROUND(Basisbedragen!$D$34*Basisbedragen!$I$2,2)),ROUND(ROUND(Basisbedragen!$D$28*0.6,4)*Basisbedragen!$I$2,2)),MIN(MAX(ROUND(ROUND('Loonschijven_Tranches salariale'!$Q19*0.6,4)*Basisbedragen!$I$7,2),ROUND(Basisbedragen!$D$34*Basisbedragen!$I$7,2)),ROUND(ROUND(Basisbedragen!$D$28*0.6,4)*Basisbedragen!$I$7,2))+Basisbedragen!$I$10) -> 78.09 | E24: =MIN(MAX(ROUND(ROUND('Loonschijven_Tranches salariale'!$Q19*0.6,4)*Basisbedragen!$I$2,2),ROUND(Basisbedragen!$D$35*Basisbedragen!$I$2,2)),ROUND(ROUND(Basisbedragen!$D$29*0.6,4)*Basisbedragen!$I$2,2)) -> 70.99 | G24: =$E$12 -> 70.99 | I24: =IF(MIN(MAX(ROUND(ROUND('Loonschijven_Tranches salariale'!$Q19*0.65,4)*Basisbedragen!$I$7,2),ROUND(Basisbedragen!$D$36*Basisbedragen!$I$7,2)),ROUND(ROUND(Basisbedragen!$D$27*0.65,4)*Basisbedragen!$I$7,2))<= Basisbedragen!$I$8,MIN(MAX(ROUND(ROUND('Loonschijven_Tranches salariale'!$Q19*0.65,4)*Basisbedragen!$I$2,2),ROUND(Basisbedragen!$D$36*Basisbedragen!$I$2,2)),ROUND(ROUND(Basisbedragen!$D$27*0.65,4)*Basisbedragen!$I$2,2)),MIN(MAX(ROUND(ROUND('Loonschijven_Tranches salariale'!$Q19*0.65,4)*Basisbedragen!$I$7,2),ROUND(Basisbedragen!$D$36*Basisbedragen!$I$7,2)),ROUND(ROUND(Basisbedragen!$D$27*0.65,4)*Basisbedragen!$I$7,2))+Basisbedragen!$I$10) -> 63.29 | J24: =IF(MIN(MAX(ROUND(ROUND('Loonschijven_Tranches salariale'!$Q19*0.6,4)*Basisbedragen!$I$7,2),ROUND(Basisbedragen!$D$36*Basisbedragen!$I$7,2)),ROUND(ROUND(Basisbedragen!$D$28*0.6,4)*Basisbedragen!$I$7,2))<= Basisbedragen!$I$8,MIN(MAX(ROUND(ROUND('Loonschijven_Tranches salariale'!$Q19*0.6,4)*Basisbedragen!$I$2,2),ROUND(Basisbedragen!$D$36*Basisbedragen!$I$2,2)),ROUND(ROUND(Basisbedragen!$D$28*0.6,4)*Basisbedragen!$I$2,2)),MIN(MAX(ROUND(ROUND('Loonschijven_Tranches salariale'!$Q19*0.6,4)*Basisbedragen!$I$7,2),ROUND(Basisbedragen!$D$36*Basisbedragen!$I$7,2)),ROUND(ROUND(Basisbedragen!$D$28*0.6,4)*Basisbedragen!$I$7,2))+Basisbedragen!$I$10) -> 63.29 | K24: =MIN(MAX(ROUND(ROUND('Loonschijven_Tranches salariale'!$Q19*0.6,4)*Basisbedragen!$I$2,2),ROUND(Basisbedragen!$D$37*Basisbedragen!$I$2,2)),ROUND(ROUND(Basisbedragen!$D$29*0.6,4)*Basisbedragen!$I$2,2)) -> 57.53 | M24: =$K$12 -> 57.53 | O24: =IF(MIN(MAX(ROUND(ROUND('Loonschijven_Tranches salariale'!$Q19*0.65,4)*Basisbedragen!$I$7,2),ROUND(Basisbedragen!$D$38*Basisbedragen!$I$7,2)),ROUND(ROUND(Basisbedragen!$D$27*0.65,4)*Basisbedragen!$I$7,2))<= Basisbedragen!$I$8,MIN(MAX(ROUND(ROUND('Loonschijven_Tranches salariale'!$Q19*0.65,4)*Basisbedragen!$I$2,2),ROUND(Basisbedragen!$D$38*Basisbedragen!$I$2,2)),ROUND(ROUND(Basisbedragen!$D$27*0.65,4)*Basisbedragen!$I$2,2)),MIN(MAX(ROUND(ROUND('Loonschijven_Tranches salariale'!$Q19*0.65,4)*Basisbedragen!$I$7,2),ROUND(Basisbedragen!$D$38*Basisbedragen!$I$7,2)),ROUND(ROUND(Basisbedragen!$D$27*0.65,4)*Basisbedragen!$I$7,2))+Basisbedragen!$I$10) -> 60.92 | P24: =IF(MIN(MAX(ROUND(ROUND('Loonschijven_Tranches salariale'!$Q19*0.6,4)*Basisbedragen!$I$7,2),ROUND(Basisbedragen!$D$39*Basisbedragen!$I$7,2)),ROUND(ROUND(Basisbedragen!$D$28*0.6,4)*Basisbedragen!$I$7,2))<= Basisbedragen!$I$8,MIN(MAX(ROUND(ROUND('Loonschijven_Tranches salariale'!$Q19*0.6,4)*Basisbedragen!$I$2,2),ROUND(Basisbedragen!$D$39*Basisbedragen!$I$2,2)),ROUND(ROUND(Basisbedragen!$D$28*0.6,4)*Basisbedragen!$I$2,2)),MIN(MAX(ROUND(ROUND('Loonschijven_Tranches salariale'!$Q19*0.6,4)*Basisbedragen!$I$7,2),ROUND(Basisbedragen!$D$39*Basisbedragen!$I$7,2)),ROUND(ROUND(Basisbedragen!$D$28*0.6,4)*Basisbedragen!$I$7,2))+Basisbedragen!$I$10) -> 56.23 | Q24: =MIN(MAX(ROUND(ROUND('Loonschijven_Tranches salariale'!$Q19*0.6,4)*Basisbedragen!$I$2,2),ROUND(Basisbedragen!$D$40*Basisbedragen!$I$2,2)),ROUND(ROUND(Basisbedragen!$D$29*0.6,4)*Basisbedragen!$I$2,2)) -> 51.12 | S24: =$S$12 -> 42.37 | T24: =$T$12 -> 29.85
